[2024-11-21T08:01:57.157+0000] {local_task_job_runner.py:123} INFO - ::group::Pre task execution logs
[2024-11-21T08:01:57.170+0000] {taskinstance.py:2612} INFO - Dependencies all met for dep_context=non-requeueable deps ti=<TaskInstance: projet_group.push scheduled__2024-11-20T11:40:00+00:00 [queued]>
[2024-11-21T08:01:57.177+0000] {taskinstance.py:2612} INFO - Dependencies all met for dep_context=requeueable deps ti=<TaskInstance: projet_group.push scheduled__2024-11-20T11:40:00+00:00 [queued]>
[2024-11-21T08:01:57.177+0000] {taskinstance.py:2865} INFO - Starting attempt 1 of 1
[2024-11-21T08:01:57.189+0000] {taskinstance.py:2888} INFO - Executing <Task(PythonOperator): push> on 2024-11-20 11:40:00+00:00
[2024-11-21T08:01:57.198+0000] {warnings.py:112} WARNING - /home/***/.local/lib/python3.12/site-packages/***/task/task_runner/standard_task_runner.py:70: DeprecationWarning: This process (pid=8497) is multi-threaded, use of fork() may lead to deadlocks in the child.
  pid = os.fork()

[2024-11-21T08:01:57.199+0000] {standard_task_runner.py:72} INFO - Started process 8504 to run task
[2024-11-21T08:01:57.199+0000] {standard_task_runner.py:104} INFO - Running: ['***', 'tasks', 'run', 'projet_group', 'push', 'scheduled__2024-11-20T11:40:00+00:00', '--job-id', '19974', '--raw', '--subdir', 'DAGS_FOLDER/projet_group.py', '--cfg-path', '/tmp/tmpjw9rkyhg']
[2024-11-21T08:01:57.200+0000] {standard_task_runner.py:105} INFO - Job 19974: Subtask push
[2024-11-21T08:01:57.239+0000] {task_command.py:467} INFO - Running <TaskInstance: projet_group.push scheduled__2024-11-20T11:40:00+00:00 [running]> on host 5365fe4338c6
[2024-11-21T08:01:57.311+0000] {taskinstance.py:3131} INFO - Exporting env vars: AIRFLOW_CTX_DAG_OWNER='***' AIRFLOW_CTX_DAG_ID='projet_group' AIRFLOW_CTX_TASK_ID='push' AIRFLOW_CTX_EXECUTION_DATE='2024-11-20T11:40:00+00:00' AIRFLOW_CTX_TRY_NUMBER='1' AIRFLOW_CTX_DAG_RUN_ID='scheduled__2024-11-20T11:40:00+00:00'
[2024-11-21T08:01:57.312+0000] {logging_mixin.py:190} INFO - Task instance is in running state
[2024-11-21T08:01:57.312+0000] {logging_mixin.py:190} INFO -  Previous state of the Task instance: queued
[2024-11-21T08:01:57.312+0000] {logging_mixin.py:190} INFO - Current task name:push state:running start_date:2024-11-21 08:01:57.171365+00:00
[2024-11-21T08:01:57.312+0000] {logging_mixin.py:190} INFO - Dag name:projet_group and current dag run status:running
[2024-11-21T08:01:57.313+0000] {taskinstance.py:731} INFO - ::endgroup::
[2024-11-21T08:01:57.318+0000] {taskinstance.py:3310} ERROR - Task failed with exception
Traceback (most recent call last):
  File "/home/airflow/.local/lib/python3.12/site-packages/urllib3/connection.py", line 196, in _new_conn
    sock = connection.create_connection(
           ^^^^^^^^^^^^^^^^^^^^^^^^^^^^^
  File "/home/airflow/.local/lib/python3.12/site-packages/urllib3/util/connection.py", line 60, in create_connection
    for res in socket.getaddrinfo(host, port, family, socket.SOCK_STREAM):
               ^^^^^^^^^^^^^^^^^^^^^^^^^^^^^^^^^^^^^^^^^^^^^^^^^^^^^^^^^^
  File "/usr/local/lib/python3.12/socket.py", line 976, in getaddrinfo
    for res in _socket.getaddrinfo(host, port, family, type, proto, flags):
               ^^^^^^^^^^^^^^^^^^^^^^^^^^^^^^^^^^^^^^^^^^^^^^^^^^^^^^^^^^^
socket.gaierror: [Errno -3] Temporary failure in name resolution

The above exception was the direct cause of the following exception:

Traceback (most recent call last):
  File "/home/airflow/.local/lib/python3.12/site-packages/urllib3/connectionpool.py", line 789, in urlopen
    response = self._make_request(
               ^^^^^^^^^^^^^^^^^^^
  File "/home/airflow/.local/lib/python3.12/site-packages/urllib3/connectionpool.py", line 490, in _make_request
    raise new_e
  File "/home/airflow/.local/lib/python3.12/site-packages/urllib3/connectionpool.py", line 466, in _make_request
    self._validate_conn(conn)
  File "/home/airflow/.local/lib/python3.12/site-packages/urllib3/connectionpool.py", line 1095, in _validate_conn
    conn.connect()
  File "/home/airflow/.local/lib/python3.12/site-packages/urllib3/connection.py", line 615, in connect
    self.sock = sock = self._new_conn()
                       ^^^^^^^^^^^^^^^^
  File "/home/airflow/.local/lib/python3.12/site-packages/urllib3/connection.py", line 203, in _new_conn
    raise NameResolutionError(self.host, self, e) from e
urllib3.exceptions.NameResolutionError: <urllib3.connection.HTTPSConnection object at 0x75e52eac8140>: Failed to resolve 'api.coingecko.com' ([Errno -3] Temporary failure in name resolution)

The above exception was the direct cause of the following exception:

Traceback (most recent call last):
  File "/home/airflow/.local/lib/python3.12/site-packages/requests/adapters.py", line 667, in send
    resp = conn.urlopen(
           ^^^^^^^^^^^^^
  File "/home/airflow/.local/lib/python3.12/site-packages/urllib3/connectionpool.py", line 843, in urlopen
    retries = retries.increment(
              ^^^^^^^^^^^^^^^^^^
  File "/home/airflow/.local/lib/python3.12/site-packages/urllib3/util/retry.py", line 519, in increment
    raise MaxRetryError(_pool, url, reason) from reason  # type: ignore[arg-type]
    ^^^^^^^^^^^^^^^^^^^^^^^^^^^^^^^^^^^^^^^^^^^^^^^^^^^
urllib3.exceptions.MaxRetryError: HTTPSConnectionPool(host='api.coingecko.com', port=443): Max retries exceeded with url: /api/v3/coins/bitcoin (Caused by NameResolutionError("<urllib3.connection.HTTPSConnection object at 0x75e52eac8140>: Failed to resolve 'api.coingecko.com' ([Errno -3] Temporary failure in name resolution)"))

During handling of the above exception, another exception occurred:

Traceback (most recent call last):
  File "/home/airflow/.local/lib/python3.12/site-packages/airflow/models/taskinstance.py", line 767, in _execute_task
    result = _execute_callable(context=context, **execute_callable_kwargs)
             ^^^^^^^^^^^^^^^^^^^^^^^^^^^^^^^^^^^^^^^^^^^^^^^^^^^^^^^^^^^^^
  File "/home/airflow/.local/lib/python3.12/site-packages/airflow/models/taskinstance.py", line 733, in _execute_callable
    return ExecutionCallableRunner(
           ^^^^^^^^^^^^^^^^^^^^^^^^
  File "/home/airflow/.local/lib/python3.12/site-packages/airflow/utils/operator_helpers.py", line 252, in run
    return self.func(*args, **kwargs)
           ^^^^^^^^^^^^^^^^^^^^^^^^^^
  File "/home/airflow/.local/lib/python3.12/site-packages/airflow/models/baseoperator.py", line 406, in wrapper
    return func(self, *args, **kwargs)
           ^^^^^^^^^^^^^^^^^^^^^^^^^^^
  File "/home/airflow/.local/lib/python3.12/site-packages/airflow/operators/python.py", line 238, in execute
    return_value = self.execute_callable()
                   ^^^^^^^^^^^^^^^^^^^^^^^
  File "/home/airflow/.local/lib/python3.12/site-packages/airflow/operators/python.py", line 256, in execute_callable
    return runner.run(*self.op_args, **self.op_kwargs)
           ^^^^^^^^^^^^^^^^^^^^^^^^^^^^^^^^^^^^^^^^^^^
  File "/home/airflow/.local/lib/python3.12/site-packages/airflow/utils/operator_helpers.py", line 252, in run
    return self.func(*args, **kwargs)
           ^^^^^^^^^^^^^^^^^^^^^^^^^^
  File "/opt/airflow/dags/projet_group.py", line 103, in push_sql
    df = get_price()
         ^^^^^^^^^^^
  File "/opt/airflow/dags/projet_group.py", line 39, in get_price
    for curr in get_currency():
                ^^^^^^^^^^^^^^
  File "/opt/airflow/dags/projet_group.py", line 18, in get_currency
    rep_curr = requests.get(url_curr, headers=headers)
               ^^^^^^^^^^^^^^^^^^^^^^^^^^^^^^^^^^^^^^^
  File "/home/airflow/.local/lib/python3.12/site-packages/requests/api.py", line 73, in get
    return request("get", url, params=params, **kwargs)
           ^^^^^^^^^^^^^^^^^^^^^^^^^^^^^^^^^^^^^^^^^^^^
  File "/home/airflow/.local/lib/python3.12/site-packages/requests/api.py", line 59, in request
    return session.request(method=method, url=url, **kwargs)
           ^^^^^^^^^^^^^^^^^^^^^^^^^^^^^^^^^^^^^^^^^^^^^^^^^
  File "/home/airflow/.local/lib/python3.12/site-packages/requests/sessions.py", line 589, in request
    resp = self.send(prep, **send_kwargs)
           ^^^^^^^^^^^^^^^^^^^^^^^^^^^^^^
  File "/home/airflow/.local/lib/python3.12/site-packages/requests/sessions.py", line 703, in send
    r = adapter.send(request, **kwargs)
        ^^^^^^^^^^^^^^^^^^^^^^^^^^^^^^^
  File "/home/airflow/.local/lib/python3.12/site-packages/requests/adapters.py", line 700, in send
    raise ConnectionError(e, request=request)
requests.exceptions.ConnectionError: HTTPSConnectionPool(host='api.coingecko.com', port=443): Max retries exceeded with url: /api/v3/coins/bitcoin (Caused by NameResolutionError("<urllib3.connection.HTTPSConnection object at 0x75e52eac8140>: Failed to resolve 'api.coingecko.com' ([Errno -3] Temporary failure in name resolution)"))
[2024-11-21T08:01:57.326+0000] {logging_mixin.py:190} INFO - Task instance in failure state
[2024-11-21T08:01:57.327+0000] {logging_mixin.py:190} INFO - Task start:2024-11-21 08:01:57.171365+00:00 end:2024-11-21 08:01:57.326650+00:00 duration:0.155285
[2024-11-21T08:01:57.327+0000] {logging_mixin.py:190} INFO - Task:<Task(PythonOperator): push> dag:<DAG: projet_group> dagrun:<DagRun projet_group @ 2024-11-20 11:40:00+00:00: scheduled__2024-11-20T11:40:00+00:00, state:running, queued_at: 2024-11-21 08:01:54.801754+00:00. externally triggered: False>
[2024-11-21T08:01:57.327+0000] {logging_mixin.py:190} INFO - Failure caused by HTTPSConnectionPool(host='api.coingecko.com', port=443): Max retries exceeded with url: /api/v3/coins/bitcoin (Caused by NameResolutionError("<urllib3.connection.HTTPSConnection object at 0x75e52eac8140>: Failed to resolve 'api.coingecko.com' ([Errno -3] Temporary failure in name resolution)"))
[2024-11-21T08:01:57.327+0000] {taskinstance.py:1225} INFO - Marking task as FAILED. dag_id=projet_group, task_id=push, run_id=scheduled__2024-11-20T11:40:00+00:00, execution_date=20241120T114000, start_date=20241121T080157, end_date=20241121T080157
[2024-11-21T08:01:57.334+0000] {taskinstance.py:340} INFO - ::group::Post task execution logs
[2024-11-21T08:01:57.334+0000] {standard_task_runner.py:124} ERROR - Failed to execute job 19974 for task push (HTTPSConnectionPool(host='api.coingecko.com', port=443): Max retries exceeded with url: /api/v3/coins/bitcoin (Caused by NameResolutionError("<urllib3.connection.HTTPSConnection object at 0x75e52eac8140>: Failed to resolve 'api.coingecko.com' ([Errno -3] Temporary failure in name resolution)")); 8504)
Traceback (most recent call last):
  File "/home/airflow/.local/lib/python3.12/site-packages/urllib3/connection.py", line 196, in _new_conn
    sock = connection.create_connection(
           ^^^^^^^^^^^^^^^^^^^^^^^^^^^^^
  File "/home/airflow/.local/lib/python3.12/site-packages/urllib3/util/connection.py", line 60, in create_connection
    for res in socket.getaddrinfo(host, port, family, socket.SOCK_STREAM):
               ^^^^^^^^^^^^^^^^^^^^^^^^^^^^^^^^^^^^^^^^^^^^^^^^^^^^^^^^^^
  File "/usr/local/lib/python3.12/socket.py", line 976, in getaddrinfo
    for res in _socket.getaddrinfo(host, port, family, type, proto, flags):
               ^^^^^^^^^^^^^^^^^^^^^^^^^^^^^^^^^^^^^^^^^^^^^^^^^^^^^^^^^^^
socket.gaierror: [Errno -3] Temporary failure in name resolution

The above exception was the direct cause of the following exception:

Traceback (most recent call last):
  File "/home/airflow/.local/lib/python3.12/site-packages/urllib3/connectionpool.py", line 789, in urlopen
    response = self._make_request(
               ^^^^^^^^^^^^^^^^^^^
  File "/home/airflow/.local/lib/python3.12/site-packages/urllib3/connectionpool.py", line 490, in _make_request
    raise new_e
  File "/home/airflow/.local/lib/python3.12/site-packages/urllib3/connectionpool.py", line 466, in _make_request
    self._validate_conn(conn)
  File "/home/airflow/.local/lib/python3.12/site-packages/urllib3/connectionpool.py", line 1095, in _validate_conn
    conn.connect()
  File "/home/airflow/.local/lib/python3.12/site-packages/urllib3/connection.py", line 615, in connect
    self.sock = sock = self._new_conn()
                       ^^^^^^^^^^^^^^^^
  File "/home/airflow/.local/lib/python3.12/site-packages/urllib3/connection.py", line 203, in _new_conn
    raise NameResolutionError(self.host, self, e) from e
urllib3.exceptions.NameResolutionError: <urllib3.connection.HTTPSConnection object at 0x75e52eac8140>: Failed to resolve 'api.coingecko.com' ([Errno -3] Temporary failure in name resolution)

The above exception was the direct cause of the following exception:

Traceback (most recent call last):
  File "/home/airflow/.local/lib/python3.12/site-packages/requests/adapters.py", line 667, in send
    resp = conn.urlopen(
           ^^^^^^^^^^^^^
  File "/home/airflow/.local/lib/python3.12/site-packages/urllib3/connectionpool.py", line 843, in urlopen
    retries = retries.increment(
              ^^^^^^^^^^^^^^^^^^
  File "/home/airflow/.local/lib/python3.12/site-packages/urllib3/util/retry.py", line 519, in increment
    raise MaxRetryError(_pool, url, reason) from reason  # type: ignore[arg-type]
    ^^^^^^^^^^^^^^^^^^^^^^^^^^^^^^^^^^^^^^^^^^^^^^^^^^^
urllib3.exceptions.MaxRetryError: HTTPSConnectionPool(host='api.coingecko.com', port=443): Max retries exceeded with url: /api/v3/coins/bitcoin (Caused by NameResolutionError("<urllib3.connection.HTTPSConnection object at 0x75e52eac8140>: Failed to resolve 'api.coingecko.com' ([Errno -3] Temporary failure in name resolution)"))

During handling of the above exception, another exception occurred:

Traceback (most recent call last):
  File "/home/airflow/.local/lib/python3.12/site-packages/airflow/task/task_runner/standard_task_runner.py", line 117, in _start_by_fork
    ret = args.func(args, dag=self.dag)
          ^^^^^^^^^^^^^^^^^^^^^^^^^^^^^
  File "/home/airflow/.local/lib/python3.12/site-packages/airflow/cli/cli_config.py", line 49, in command
    return func(*args, **kwargs)
           ^^^^^^^^^^^^^^^^^^^^^
  File "/home/airflow/.local/lib/python3.12/site-packages/airflow/utils/cli.py", line 115, in wrapper
    return f(*args, **kwargs)
           ^^^^^^^^^^^^^^^^^^
  File "/home/airflow/.local/lib/python3.12/site-packages/airflow/cli/commands/task_command.py", line 483, in task_run
    task_return_code = _run_task_by_selected_method(args, _dag, ti)
                       ^^^^^^^^^^^^^^^^^^^^^^^^^^^^^^^^^^^^^^^^^^^^
  File "/home/airflow/.local/lib/python3.12/site-packages/airflow/cli/commands/task_command.py", line 256, in _run_task_by_selected_method
    return _run_raw_task(args, ti)
           ^^^^^^^^^^^^^^^^^^^^^^^
  File "/home/airflow/.local/lib/python3.12/site-packages/airflow/cli/commands/task_command.py", line 341, in _run_raw_task
    return ti._run_raw_task(
           ^^^^^^^^^^^^^^^^^
  File "/home/airflow/.local/lib/python3.12/site-packages/airflow/utils/session.py", line 97, in wrapper
    return func(*args, session=session, **kwargs)
           ^^^^^^^^^^^^^^^^^^^^^^^^^^^^^^^^^^^^^^
  File "/home/airflow/.local/lib/python3.12/site-packages/airflow/models/taskinstance.py", line 3004, in _run_raw_task
    return _run_raw_task(
           ^^^^^^^^^^^^^^
  File "/home/airflow/.local/lib/python3.12/site-packages/airflow/models/taskinstance.py", line 273, in _run_raw_task
    TaskInstance._execute_task_with_callbacks(
  File "/home/airflow/.local/lib/python3.12/site-packages/airflow/models/taskinstance.py", line 3158, in _execute_task_with_callbacks
    result = self._execute_task(context, task_orig)
             ^^^^^^^^^^^^^^^^^^^^^^^^^^^^^^^^^^^^^^
  File "/home/airflow/.local/lib/python3.12/site-packages/airflow/models/taskinstance.py", line 3182, in _execute_task
    return _execute_task(self, context, task_orig)
           ^^^^^^^^^^^^^^^^^^^^^^^^^^^^^^^^^^^^^^^
  File "/home/airflow/.local/lib/python3.12/site-packages/airflow/models/taskinstance.py", line 767, in _execute_task
    result = _execute_callable(context=context, **execute_callable_kwargs)
             ^^^^^^^^^^^^^^^^^^^^^^^^^^^^^^^^^^^^^^^^^^^^^^^^^^^^^^^^^^^^^
  File "/home/airflow/.local/lib/python3.12/site-packages/airflow/models/taskinstance.py", line 733, in _execute_callable
    return ExecutionCallableRunner(
           ^^^^^^^^^^^^^^^^^^^^^^^^
  File "/home/airflow/.local/lib/python3.12/site-packages/airflow/utils/operator_helpers.py", line 252, in run
    return self.func(*args, **kwargs)
           ^^^^^^^^^^^^^^^^^^^^^^^^^^
  File "/home/airflow/.local/lib/python3.12/site-packages/airflow/models/baseoperator.py", line 406, in wrapper
    return func(self, *args, **kwargs)
           ^^^^^^^^^^^^^^^^^^^^^^^^^^^
  File "/home/airflow/.local/lib/python3.12/site-packages/airflow/operators/python.py", line 238, in execute
    return_value = self.execute_callable()
                   ^^^^^^^^^^^^^^^^^^^^^^^
  File "/home/airflow/.local/lib/python3.12/site-packages/airflow/operators/python.py", line 256, in execute_callable
    return runner.run(*self.op_args, **self.op_kwargs)
           ^^^^^^^^^^^^^^^^^^^^^^^^^^^^^^^^^^^^^^^^^^^
  File "/home/airflow/.local/lib/python3.12/site-packages/airflow/utils/operator_helpers.py", line 252, in run
    return self.func(*args, **kwargs)
           ^^^^^^^^^^^^^^^^^^^^^^^^^^
  File "/opt/airflow/dags/projet_group.py", line 103, in push_sql
    df = get_price()
         ^^^^^^^^^^^
  File "/opt/airflow/dags/projet_group.py", line 39, in get_price
    for curr in get_currency():
                ^^^^^^^^^^^^^^
  File "/opt/airflow/dags/projet_group.py", line 18, in get_currency
    rep_curr = requests.get(url_curr, headers=headers)
               ^^^^^^^^^^^^^^^^^^^^^^^^^^^^^^^^^^^^^^^
  File "/home/airflow/.local/lib/python3.12/site-packages/requests/api.py", line 73, in get
    return request("get", url, params=params, **kwargs)
           ^^^^^^^^^^^^^^^^^^^^^^^^^^^^^^^^^^^^^^^^^^^^
  File "/home/airflow/.local/lib/python3.12/site-packages/requests/api.py", line 59, in request
    return session.request(method=method, url=url, **kwargs)
           ^^^^^^^^^^^^^^^^^^^^^^^^^^^^^^^^^^^^^^^^^^^^^^^^^
  File "/home/airflow/.local/lib/python3.12/site-packages/requests/sessions.py", line 589, in request
    resp = self.send(prep, **send_kwargs)
           ^^^^^^^^^^^^^^^^^^^^^^^^^^^^^^
  File "/home/airflow/.local/lib/python3.12/site-packages/requests/sessions.py", line 703, in send
    r = adapter.send(request, **kwargs)
        ^^^^^^^^^^^^^^^^^^^^^^^^^^^^^^^
  File "/home/airflow/.local/lib/python3.12/site-packages/requests/adapters.py", line 700, in send
    raise ConnectionError(e, request=request)
requests.exceptions.ConnectionError: HTTPSConnectionPool(host='api.coingecko.com', port=443): Max retries exceeded with url: /api/v3/coins/bitcoin (Caused by NameResolutionError("<urllib3.connection.HTTPSConnection object at 0x75e52eac8140>: Failed to resolve 'api.coingecko.com' ([Errno -3] Temporary failure in name resolution)"))
[2024-11-21T08:01:57.374+0000] {local_task_job_runner.py:266} INFO - Task exited with return code 1
[2024-11-21T08:01:57.385+0000] {taskinstance.py:3900} INFO - 0 downstream tasks scheduled from follow-on schedule check
[2024-11-21T08:01:57.386+0000] {local_task_job_runner.py:245} INFO - ::endgroup::
